Workbook
Name alpha: #REF!
Name b_inh: #REF!
Name C_wall: #REF!
Name chi: #REF!
Name EI_wall: #REF!
Name gamma_sat: #REF!
Name gammaM2: #REF!
Name L_wall: #REF!
Name Len: #REF!
Name Su: #REF!
Name su_c: #REF!

Sheet Introduction
B2: v2.0.0
B3: MSD Walls Spreadsheet Calculation
B5: v2.0.0 Authors:
B6: J.J Crispin, A.H. Bateman, Z. Struzik, E. Voyagaki, G. Mylonakis and P.J. Vardanega
B8: Technical Appendix:
B9: Please see accompanying technical appendix at: https://github.com/AbiBateman/MSD_Walls
B11: Relevent papers:
B12: Hua, Y., Struzik, Z., Bateman, A.H., Crispin, J.J., Huang, H., Zhang, D., Mylonakis, G.E. & Vardanega, P.J. (2026). Assessing the effectiveness of the mobilizable strength design method for prediction of retaining wall movements using a database, submitted.
B14: Crispin, J.J., Bateman, A.H., Voyagaki, E., Campbell, A., Mylonakis, G., Bolton, M.D. & Vardanega, P.J. (2023). MSD applied to the construction of the British Library basement: a multistage excavation in London Clay. Canadian Geotechnical Journal, https://doi.org/10.1139/cgj-2023-0238
B16: Disclaimer:
B17: This spreadsheet is provided by the authors to show the derivation of the MSD predictions. It is not intended to be used or relied upon (in whole or part) for any other purpose, and no warranty is provided or implied. While every effort has been made, the authors cannot guarentee that this spreadsheet is error free.
B19: Notes:
... B31: 2.0.0

Sheet MSD Calculation
B2: Input Properties | G2: Pure Rotation Stage | L2: Bulging Stages
B3: Input parameters required in the calculation are highlighted in green. These are defined in the technical appendix. | G3: This section calculates the incremental maximum displacement in Stage 1 of the calculation (pure rotation stage). This is detailed in Section 1 of the technical appendix. | L3: This section calculates the incremental maximum displacement in the bulging stages of the calculation (Stage 2 onwards). This is detailed in Section 2 of the technical appendix. The general solution requires an iterative approach (discussed in the technical appendix). Under the key results tab at the top, the "closed form" maximum incremental displacements are shown first, followed in green by the "guess" maximum incremental displacement, followed by the "result" incremental diplsacement from the general solution. The percentage error between the "guess" and the "result" is shown below which will highlight in red if the error is larger than the "tolerable error" defined in the input parameters. The "guess" needs (very small) changes until it matches the "result" incremental maximum displacement (to the desired tolerance).
B4: Wall Properties | H4: Eq. Number | I4: Value | J4: Units | L4: Key Results
B5: Length of wall, L | D5: =25+4.6 -> 29.6 | E5: m | G5: Incremental max. displacement, δwmax,1 | H5: A1b | I5: =(D5*D20/2)*(D16*D25*(3-3*D25/D5+(D25/D5)^2)/(3*D17*(2-2*(D25/D5)+(D25/D5)^2)+D18*D5*(2-3*(D25/D5)^2+2*(D25/D5)^3)))^(1/D19) -> 0.014153523 | J5: m | N5: Stage 2 | O5: Stage 3 | P5: Stage 4 | Q5: Stage 5 | R5: Units
B6: αλ | D6: 1.2 | G6: Incremental max. displacement, δwmax,1 | H6: A1b | I6: =I5*1000 -> 14.153523 | J6: mm | L6: Incremental max. displacement, δwmax,m (closed-form) | N6: =N32 -> 0.006745093 | O6: =O32 -> 0.0031360146 | P6: =P32 -> 0.001729593 | Q6: =Q32 -> 0.00045098854 | R6: m
B7: Poisson's Ratio of the wall, ν | D7: 0.2 | G7: Mobilisation factor, βm | H7: A11a | I7: =1/2*(I8/D20)^D19 -> 0.15760238 | L7: Incremental max. displacement, δwmax,m (guess) | N7: 0.00975 | O7: 0.003718 | P7: 0.002015 | Q7: 0.000575 | R7: m
B8: Concrete Young's modulus, Ec | D8: 31000000 | E8: kPa | G8: Average shear strain in the mechanism, γave,m | I8: =2*I5/D5 -> 0.00095631909 | L8: Incremental max. displacement, δwmax,m (result) | N8: =N44 -> 0.0096995619 | O8: =O44 -> 0.0036949561 | P8: =P44 -> 0.0020171788 | Q8: =Q44 -> 0.00057865486 | R8: m
B9: Concrete Second Moment of Area, Ic | D9: =PI()/4*(0.59^4)/1.95 -> 0.048804888 | E9: m4 | L9: Percentage Error (abs) | N9: =ABS((N7-N8)/N8) -> 0.0052000422 | O9: =ABS((O7-O8)/O8) -> 0.0062365754 | P9: =ABS((P7-P8)/P8) -> 0.0010801378 | Q9: =ABS((Q7-Q8)/Q8) -> 0.0063161312
B10: Steel Young's modulus, Es | D10: 210000000 | E10: kPa | L10: Incremental max. displacement, δwmax,m | N10: =N8*1000 -> 9.6995619 | O10: =O8*1000 -> 3.6949561 | P10: =P8*1000 -> 2.0171788 | Q10: =Q8*1000 -> 0.57865486 | R10: mm
B11: Steel Second Moment of Area, Is | D11: =(5041866675+446688928)*10^(-12)/1.95 -> 0.0028146439 | E11: m4 | L11: Mobilisation factor, βm | N11: =N47 -> 0.12598037 | O11: =O47 -> 0.15776564 | P11: =P47 -> 0.17790377 | Q11: =Q47 -> 0.18594024
B12: EI = (EcIc + EsIs)/(1-νs2) | D12: =(D8*D9+D10*D11)/(1-D7^2) -> 2191694.5 | E12: kNm2/m | L12: Average shear strain in the mechanism, γave,m | N12: =N46 -> 0.00065 | O12: =O46 -> 0.00095802774 | P12: =P46 -> 0.001178504 | Q12: =Q46 -> 0.0012717865
B15: Soil Properties | L15: Bulging Stage Dimensions
B16: Saturated unit weight, γsat | D16: 20 | E16: kN/m3 | N16: Stage 2 | O16: Stage 3 | P16: Stage 4 | Q16: Stage 5 | R16: Units
B17: Undrained shear strength at the surface, su,0 | D17: 40 | E17: kPa | L17: Excavation depths, Hm | N17: =D26 -> 10.3 | O17: =D27 -> 15.1 | P17: =D28 -> 19.9 | Q17: =D29 -> 24.9 | R17: m
B18: Variation of su with depth, su,var | D18: 11 | E18: kPa/m | L18: Lowest prop depth, Hp,m | N18: =D30 -> 4.6 | O18: =D31 -> 9.7 | P18: =D32 -> 14.5 | Q18: =D33 -> 19.3 | R18: m
B19: Soil non-linearity exponent, b | D19: 0.58 | L19: Distance between prop and base of wall, sm | N19: =$D$5-N18 -> 25 | O19: =$D$5-O18 -> 19.9 | P19: =$D$5-P18 -> 15.1 | Q19: =$D$5-Q18 -> 10.3 | R19: m
B20: Shear strain at τ/su = 0.5, γ50 | D20: 0.007 | L20: Wavelength of the deformation mechanism, λm (Eq. A3) | N20: =N19*$D$6 -> 30 | O20: =O19*$D$6 -> 23.88 | P20: =P19*$D$6 -> 18.12 | Q20: =Q19*$D$6 -> 12.36 | R20: m
L21: Distance between excavation depth and prop, hp,m | N21: =N17-N18 -> 5.7 | O21: =O17-O18 -> 5.4 | P21: =P17-P18 -> 5.4 | Q21: =Q17-Q18 -> 5.6 | R21: m
B23: Excavation Depths (measured below top of wall)
B24: Reduced Level of top of wall | D24: 18.5 | E24: mAOD | L24: Closed Form solution (assuming b = 0.5)
B25: Excavation depths, Hm | C25: Stage 1, H1 | D25: 5.2 | E25: m | M25: Eq. Number | N25: Stage 2 | O25: Stage 3 | P25: Stage 4 | Q25: Stage 5 | R25: Units
C26: Stage 2, H2 | D26: 10.3 | E26: m | L26: A | M26: A6 | N26: =N53 -> 3071.6003 | O26: =O53 -> 3582.9447 | P26: =P53 -> 3567.9591 | Q26: =Q53 -> 2996.5641 | R26: kN/m
C27: Stage 3, H3 | D27: 15.1 | E27: m | L27: Bmax | M27: A7a | N27: =N69 -> 23916.212 | O27: =O69 -> 21783.404 | P27: =P69 -> 19090.165 | Q27: =Q69 -> 15607.317 | R27: kN/m
C28: Stage 4, H4 | D28: 19.9 | E28: m | L28: C1 | M28: A8b | N28: =PI()^4*$D$12/N20^3*(1/$D$6+1/(4*PI())*SIN(4*PI()/$D$6)) -> 6044.3028 | O28: =PI()^4*$D$12/O20^3*(1/$D$6+1/(4*PI())*SIN(4*PI()/$D$6)) -> 11984.144 | P28: =PI()^4*$D$12/P20^3*(1/$D$6+1/(4*PI())*SIN(4*PI()/$D$6)) -> 27430.605 | Q28: =PI()^4*$D$12/Q20^3*(1/$D$6+1/(4*PI())*SIN(4*PI()/$D$6)) -> 86428.02 | R28: kN/m2
C29: Stage 5, H5 | D29: 24.9 | E29: m | L29: C2 | M29: A8c | N29: 0 | O29: =PI()^3*$D$12*(N32/(N20^3*(1+O20/N20))*(2/(O20/N20-1)*SIN(2*PI()/$D$6*(O20/N20-1))+N20/O20*SIN(4*PI()/$D$6))) -> 70.924793 | P29: =PI()^3*$D$12*(N32/(N20^3*(1+P20/N20))*(2/(P20/N20-1)*SIN(2*PI()/$D$6*(P20/N20-1))+N20/P20*SIN(4*PI()/$D$6))+O32/(O20^3*(1+P20/O20))*(2/(P20/O20-1)*SIN(2*PI()/$D$6*(P20/O20-1))+O20/P20*SIN(4*PI()/$D$6))) -> 91.822024 | Q29: =PI()^3*$D$12*(N32/(N20^3*(1+Q20/N20))*(2/(Q20/N20-1)*SIN(2*PI()/$D$6*(Q20/N20-1))+N20/Q20*SIN(4*PI()/$D$6))+O32/(O20^3*(1+Q20/O20))*(2/(Q20/O20-1)*SIN(2*PI()/$D$6*(Q20/O20-1))+O20/Q20*SIN(4*PI()/$D$6))+P32/(P20^3*(1+Q20/P20))*(2/(Q20/P20-1)*SIN(2*PI()/$D$6*(Q20/P20-1))+P20/Q20*SIN(4*PI()/$D$6))) -> 43.390287 | R29: kN/m
B30: Lowest prop depth, Hp,m | C30: Stage 2, Hp,2 | D30: 4.6 | E30: m | L30: χ1 | M30: A12b | N30: 0 | O30: =$D$38/(4*$D$20)*(N32/N20) -> 0.016059745 | P30: =$D$38/(4*$D$20)*(N32/N20+O32/O20) -> 0.025440023 | Q30: =$D$38/(4*$D$20)*(N32/N20+O32/O20+P32/P20) -> 0.032258035
C31: Stage 3, Hp,3 | D31: 9.7 | E31: m | L31: χ2 | M31: A12c | N31: =$D$38/(4*N20*$D$20) -> 2.3809524 | O31: =$D$38/(4*O20*$D$20) -> 2.9911462 | P31: =$D$38/(4*P20*$D$20) -> 3.9419741 | Q31: =$D$38/(4*Q20*$D$20) -> 5.7790106 | R31: 1/m
C32: Stage 4, Hp,4 | D32: 14.5 | E32: m | L32: Incremental max. displacement, δwmax,m | M32: A13a | N32: =1/(2*N28^2)*(N27^2*N31+2*N28*(N26-N29)-N27*SQRT(N27^2*N31^2+4*N31*N28*N26+4*N30*N28^2-4*N31*N28*N29)) -> 0.006745093 | O32: =1/(2*O28^2)*(O27^2*O31+2*O28*(O26-O29)-O27*SQRT(O27^2*O31^2+4*O31*O28*O26+4*O30*O28^2-4*O31*O28*O29)) -> 0.0031360146 | P32: =1/(2*P28^2)*(P27^2*P31+2*P28*(P26-P29)-P27*SQRT(P27^2*P31^2+4*P31*P28*P26+4*P30*P28^2-4*P31*P28*P29)) -> 0.001729593 | Q32: =1/(2*Q28^2)*(Q27^2*Q31+2*Q28*(Q26-Q29)-Q27*SQRT(Q27^2*Q31^2+4*Q31*Q28*Q26+4*Q30*Q28^2-4*Q31*Q28*Q29)) -> 0.00045098854 | R32: m
C33: Stage 5, Hp,5 | D33: 19.3 | E33: m | L33: Incremental max. displacement, δwmax,m | M33: A13a | N33: =N32*1000 -> 6.745093 | O33: =O32*1000 -> 3.1360146 | P33: =P32*1000 -> 1.729593 | Q33: =Q32*1000 -> 0.45098854 | R33: mm
L34: Average shear strain within the mechanism, γave,m | M34: A10b | N34: =$D$38*(N32/N20) -> 0.00044967287 | O34: =$D$38*(N32/N20+O32/O20) -> 0.00071232066 | P34: =$D$38*(N32/N20+O32/O20+P32/P20) -> 0.00090322497 | Q34: =$D$38*(N32/N20+O32/O20+P32/P20+Q32/Q20) -> 0.00097620046
L35: Mobilisation factor, βm | M35: A10a | N35: =1/2*(N34/$D$20)^$D$19 -> 0.10174035 | O35: =1/2*(O34/$D$20)^$D$19 -> 0.13285104 | P35: =1/2*(P34/$D$20)^$D$19 -> 0.15246662 | Q35: =1/2*(Q34/$D$20)^$D$19 -> 0.15949452
B36: Model Parameters
B37: Iteration Tolerance | D37: 0.01
B38: Similarity factor, Mc | D38: 2 | L38: General Solution
M39: Eq. Number | N39: Stage 2 | O39: Stage 3 | P39: Stage 4 | Q39: Stage 5 | R39: Units
L40: A | M40: A6 | N40: =N53 -> 3071.6003 | O40: =O53 -> 3582.9447 | P40: =P53 -> 3567.9591 | Q40: =Q53 -> 2996.5641 | R40: kN/m
L41: B | M41: A7a | N41: =N69*N47 -> 3012.9732 | O41: =O69*O47 -> 3436.6727 | P41: =P69*P47 -> 3396.2123 | Q41: =Q69*Q47 -> 2902.0282 | R41: kN/m
L42: C1 | M42: A8b | N42: =N28 -> 6044.3028 | O42: =O28 -> 11984.144 | P42: =P28 -> 27430.605 | Q42: =Q28 -> 86428.02 | R42: kN/m2
L43: C2 | M43: A8c | N43: 0 | O43: =PI()^3*$D$12*(N44/(N20^3*(1+O20/N20))*(2/(O20/N20-1)*SIN(2*PI()/$D$6*(O20/N20-1))+N20/O20*SIN(4*PI()/$D$6))) -> 101.99109 | P43: =PI()^3*$D$12*(N44/(N20^3*(1+P20/N20))*(2/(P20/N20-1)*SIN(2*PI()/$D$6*(P20/N20-1))+N20/P20*SIN(4*PI()/$D$6))+O44/(O20^3*(1+P20/O20))*(2/(P20/O20-1)*SIN(2*PI()/$D$6*(P20/O20-1))+O20/P20*SIN(4*PI()/$D$6))) -> 116.41435 | Q43: =PI()^3*$D$12*(N44/(N20^3*(1+Q20/N20))*(2/(Q20/N20-1)*SIN(2*PI()/$D$6*(Q20/N20-1))+N20/Q20*SIN(4*PI()/$D$6))+O44/(O20^3*(1+Q20/O20))*(2/(Q20/O20-1)*SIN(2*PI()/$D$6*(Q20/O20-1))+O20/Q20*SIN(4*PI()/$D$6))+P44/(P20^3*(1+Q20/P20))*(2/(Q20/P20-1)*SIN(2*PI()/$D$6*(Q20/P20-1))+P20/Q20*SIN(4*PI()/$D$6))) -> 44.523959 | R43: kN/m
L44: Incremental max. displacement, δwmax,m | M44: A9 | N44: =(N40-N41-N43)/N42 -> 0.0096995619 | O44: =(O40-O41-O43)/O42 -> 0.0036949561 | P44: =(P40-P41-P43)/P42 -> 0.0020171788 | Q44: =(Q40-Q41-Q43)/Q42 -> 0.00057865486 | R44: m
...

Sheet Plotting
B2: Key Output Properties | L2: Input Properties
E3: Stage 1 | F3: Stage 2 | G3: Stage 3 | H3: Stage 4 | I3: Stage 5 | J3: Units | L3: Number of data points plotted per meter depth (limit 100) | N3: 100
B4: Excavation depths, Hm | E4: ='MSD Calculation'!D25 -> 5.2 | F4: ='MSD Calculation'!N17 -> 10.3 | G4: ='MSD Calculation'!O17 -> 15.1 | H4: ='MSD Calculation'!P17 -> 19.9 | I4: ='MSD Calculation'!Q17 -> 24.9 | J4: m | L4: Plotted results ("Closed-form" or "General") | N4: General
B5: Lowest prop depth, Hp,m | F5: ='MSD Calculation'!N18 -> 4.6 | G5: ='MSD Calculation'!O18 -> 9.7 | H5: ='MSD Calculation'!P18 -> 14.5 | I5: ='MSD Calculation'!Q18 -> 19.3 | J5: m
B6: Wavelength of the deformation mechanism, λm | F6: ='MSD Calculation'!N20 -> 30 | G6: ='MSD Calculation'!O20 -> 23.88 | H6: ='MSD Calculation'!P20 -> 18.12 | I6: ='MSD Calculation'!Q20 -> 12.36 | J6: m | L6: Plotting Notes
B7: Incremental max. displacement, δwmax,1 (rotation) | E7: ='MSD Calculation'!I5 -> 0.014153523 | J7: m | L7: Key results from the previous sheet are provided on the left for convience. Both the general and closed form solutions can be plotted (selected above). Incremental displacements for each stage are plotted on the left, total displacements for each stage are plotted on the right. The number of data points per meter along the wall can be selected (limit 100). The limits on both plots will need updating for different problems.
B8: Incremental max. displacement, δwmax,m (closed-form) | F8: ='MSD Calculation'!N6 -> 0.006745093 | G8: ='MSD Calculation'!O6 -> 0.0031360146 | H8: ='MSD Calculation'!P6 -> 0.001729593 | I8: ='MSD Calculation'!Q6 -> 0.00045098854 | J8: m
B9: Incremental max. displacement, δwmax,m (result) | F9: ='MSD Calculation'!N8 -> 0.0096995619 | G9: ='MSD Calculation'!O8 -> 0.0036949561 | H9: ='MSD Calculation'!P8 -> 0.0020171788 | I9: ='MSD Calculation'!Q8 -> 0.00057865486 | J9: m
B11: Incremental Displacements, δwm | L11: Total Displacements, wm
B15: Depth, y | C15: Normalised Depth, y/L | D15: Reduced Level (mAOD) | E15: Stage 1 | F15: Stage 2 | G15: Stage 3 | H15: Stage 4 | I15: Stage 5 | J15: Units | L15: Depth, y | M15: Normalised Depth, y/L | N15: Reduced Level (mAOD) | O15: Stage 1 | P15: Stage 2 | Q15: Stage 3 | R15: Stage 4 | S15: Stage 5 | T15: Units
E16: Eq. A1a | F16: Eq. A2 | G16: Eq. A2 | H16: Eq. A2 | I16: Eq. A2 | O16: Eq. A1a | P16: Eq. A11 | Q16: Eq. A11 | R16: Eq. A11 | S16: Eq. A11
B17: {=_xlfn.SEQUENCE('MSD Calculation'!$D$5*$N$3+1,1,0,1/$N$3)} -> 0 | C17: =B17/'MSD Calculation'!$D$5 -> 0 | D17: ='MSD Calculation'!$D$24-B17 -> 18.5 | E17: =IF(B17="",0,IF(B17<'MSD Calculation'!$D$5,$E$7*(1-B17/'MSD Calculation'!$D$5), 0)) -> 0.014153523 | F17: =IF(B17="",0,IF($B17<$F$5,0,IF($B17>'MSD Calculation'!$D$5,0,IF($N$4="Closed-form",1/2*(1-COS(2*PI()*($B17-$F$5)/$F$6))*$F$8,IF($N$4="General",1/2*(1-COS(2*PI()*($B17-$F$5)/$F$6))*$F$9,"Error"))))) -> 0 | G17: =IF(B17="",0,IF($B17<$G$5,0,IF($B17>'MSD Calculation'!$D$5,0,IF($N$4="Closed-form",1/2*(1-COS(2*PI()*($B17-$G$5)/$G$6))*$G$8,IF($N$4="General",1/2*(1-COS(2*PI()*($B17-$G$5)/$G$6))*$G$9,"Error"))))) -> 0 | H17: =IF(B17="",0,IF($B17<$H$5,0,IF($B17>'MSD Calculation'!$D$5,0,IF($N$4="Closed-form",1/2*(1-COS(2*PI()*($B17-$H$5)/$H$6))*$H$8,IF($N$4="General",1/2*(1-COS(2*PI()*($B17-$H$5)/$H$6))*$H$9,"Error"))))) -> 0 | I17: =IF(B17="",0,IF($B17<$I$5,0,IF($B17>'MSD Calculation'!$D$5,0,IF($N$4="Closed-form",1/2*(1-COS(2*PI()*($B17-$I$5)/$I$6))*$I$8,IF($N$4="General",1/2*(1-COS(2*PI()*($B17-$I$5)/$I$6))*$I$9,"Error"))))) -> 0 | J17: m | L17: {=_xlfn.SEQUENCE('MSD Calculation'!$D$5*$N$3+1,1,0,1/$N$3)} -> 0 | M17: =L17/'MSD Calculation'!$D$5 -> 0 | N17: ='MSD Calculation'!$D$24-L17 -> 18.5 | O17: =E17 -> 0.014153523 | P17: =E17+F17 -> 0.014153523 | Q17: =E17+F17+G17 -> 0.014153523 | R17: =+E17+F17+G17+H17 -> 0.014153523 | S17: =E17+F17+G17+H17+I17 -> 0.014153523 | T17: m
B18: 0.01 | C18: =B18/'MSD Calculation'!$D$5 -> 0.00033783784 | D18: ='MSD Calculation'!$D$24-B18 -> 18.49 | E18: =IF(B18="",0,IF(B18<'MSD Calculation'!$D$5,$E$7*(1-B18/'MSD Calculation'!$D$5), 0)) -> 0.014148741 | F18: =IF(B18="",0,IF($B18<$F$5,0,IF($B18>'MSD Calculation'!$D$5,0,IF($N$4="Closed-form",1/2*(1-COS(2*PI()*($B18-$F$5)/$F$6))*$F$8,IF($N$4="General",1/2*(1-COS(2*PI()*($B18-$F$5)/$F$6))*$F$9,"Error"))))) -> 0 | G18: =IF(B18="",0,IF($B18<$G$5,0,IF($B18>'MSD Calculation'!$D$5,0,IF($N$4="Closed-form",1/2*(1-COS(2*PI()*($B18-$G$5)/$G$6))*$G$8,IF($N$4="General",1/2*(1-COS(2*PI()*($B18-$G$5)/$G$6))*$G$9,"Error"))))) -> 0 | H18: =IF(B18="",0,IF($B18<$H$5,0,IF($B18>'MSD Calculation'!$D$5,0,IF($N$4="Closed-form",1/2*(1-COS(2*PI()*($B18-$H$5)/$H$6))*$H$8,IF($N$4="General",1/2*(1-COS(2*PI()*($B18-$H$5)/$H$6))*$H$9,"Error"))))) -> 0 | I18: =IF(B18="",0,IF($B18<$I$5,0,IF($B18>'MSD Calculation'!$D$5,0,IF($N$4="Closed-form",1/2*(1-COS(2*PI()*($B18-$I$5)/$I$6))*$I$8,IF($N$4="General",1/2*(1-COS(2*PI()*($B18-$I$5)/$I$6))*$I$9,"Error"))))) -> 0 | J18: m | L18: 0.01 | M18: =L18/'MSD Calculation'!$D$5 -> 0.00033783784 | N18: ='MSD Calculation'!$D$24-L18 -> 18.49 | O18: =E18 -> 0.014148741 | P18: =E18+F18 -> 0.014148741 | Q18: =E18+F18+G18 -> 0.014148741 | R18: =+E18+F18+G18+H18 -> 0.014148741 | S18: =E18+F18+G18+H18+I18 -> 0.014148741 | T18: m
B19: 0.02 | C19: =B19/'MSD Calculation'!$D$5 -> 0.00067567568 | D19: ='MSD Calculation'!$D$24-B19 -> 18.48 | E19: =IF(B19="",0,IF(B19<'MSD Calculation'!$D$5,$E$7*(1-B19/'MSD Calculation'!$D$5), 0)) -> 0.014143959 | F19: =IF(B19="",0,IF($B19<$F$5,0,IF($B19>'MSD Calculation'!$D$5,0,IF($N$4="Closed-form",1/2*(1-COS(2*PI()*($B19-$F$5)/$F$6))*$F$8,IF($N$4="General",1/2*(1-COS(2*PI()*($B19-$F$5)/$F$6))*$F$9,"Error"))))) -> 0 | G19: =IF(B19="",0,IF($B19<$G$5,0,IF($B19>'MSD Calculation'!$D$5,0,IF($N$4="Closed-form",1/2*(1-COS(2*PI()*($B19-$G$5)/$G$6))*$G$8,IF($N$4="General",1/2*(1-COS(2*PI()*($B19-$G$5)/$G$6))*$G$9,"Error"))))) -> 0 | H19: =IF(B19="",0,IF($B19<$H$5,0,IF($B19>'MSD Calculation'!$D$5,0,IF($N$4="Closed-form",1/2*(1-COS(2*PI()*($B19-$H$5)/$H$6))*$H$8,IF($N$4="General",1/2*(1-COS(2*PI()*($B19-$H$5)/$H$6))*$H$9,"Error"))))) -> 0 | I19: =IF(B19="",0,IF($B19<$I$5,0,IF($B19>'MSD Calculation'!$D$5,0,IF($N$4="Closed-form",1/2*(1-COS(2*PI()*($B19-$I$5)/$I$6))*$I$8,IF($N$4="General",1/2*(1-COS(2*PI()*($B19-$I$5)/$I$6))*$I$9,"Error"))))) -> 0 | J19: m | L19: 0.02 | M19: =L19/'MSD Calculation'!$D$5 -> 0.00067567568 | N19: ='MSD Calculation'!$D$24-L19 -> 18.48 | O19: =E19 -> 0.014143959 | P19: =E19+F19 -> 0.014143959 | Q19: =E19+F19+G19 -> 0.014143959 | R19: =+E19+F19+G19+H19 -> 0.014143959 | S19: =E19+F19+G19+H19+I19 -> 0.014143959 | T19: m
B20: 0.03 | C20: =B20/'MSD Calculation'!$D$5 -> 0.0010135135 | D20: ='MSD Calculation'!$D$24-B20 -> 18.47 | E20: =IF(B20="",0,IF(B20<'MSD Calculation'!$D$5,$E$7*(1-B20/'MSD Calculation'!$D$5), 0)) -> 0.014139178 | F20: =IF(B20="",0,IF($B20<$F$5,0,IF($B20>'MSD Calculation'!$D$5,0,IF($N$4="Closed-form",1/2*(1-COS(2*PI()*($B20-$F$5)/$F$6))*$F$8,IF($N$4="General",1/2*(1-COS(2*PI()*($B20-$F$5)/$F$6))*$F$9,"Error"))))) -> 0 | G20: =IF(B20="",0,IF($B20<$G$5,0,IF($B20>'MSD Calculation'!$D$5,0,IF($N$4="Closed-form",1/2*(1-COS(2*PI()*($B20-$G$5)/$G$6))*$G$8,IF($N$4="General",1/2*(1-COS(2*PI()*($B20-$G$5)/$G$6))*$G$9,"Error"))))) -> 0 | H20: =IF(B20="",0,IF($B20<$H$5,0,IF($B20>'MSD Calculation'!$D$5,0,IF($N$4="Closed-form",1/2*(1-COS(2*PI()*($B20-$H$5)/$H$6))*$H$8,IF($N$4="General",1/2*(1-COS(2*PI()*($B20-$H$5)/$H$6))*$H$9,"Error"))))) -> 0 | I20: =IF(B20="",0,IF($B20<$I$5,0,IF($B20>'MSD Calculation'!$D$5,0,IF($N$4="Closed-form",1/2*(1-COS(2*PI()*($B20-$I$5)/$I$6))*$I$8,IF($N$4="General",1/2*(1-COS(2*PI()*($B20-$I$5)/$I$6))*$I$9,"Error"))))) -> 0 | J20: m | L20: 0.03 | M20: =L20/'MSD Calculation'!$D$5 -> 0.0010135135 | N20: ='MSD Calculation'!$D$24-L20 -> 18.47 | O20: =E20 -> 0.014139178 | P20: =E20+F20 -> 0.014139178 | Q20: =E20+F20+G20 -> 0.014139178 | R20: =+E20+F20+G20+H20 -> 0.014139178 | S20: =E20+F20+G20+H20+I20 -> 0.014139178 | T20: m
B21: 0.04 | C21: =B21/'MSD Calculation'!$D$5 -> 0.0013513514 | D21: ='MSD Calculation'!$D$24-B21 -> 18.46 | E21: =IF(B21="",0,IF(B21<'MSD Calculation'!$D$5,$E$7*(1-B21/'MSD Calculation'!$D$5), 0)) -> 0.014134396 | F21: =IF(B21="",0,IF($B21<$F$5,0,IF($B21>'MSD Calculation'!$D$5,0,IF($N$4="Closed-form",1/2*(1-COS(2*PI()*($B21-$F$5)/$F$6))*$F$8,IF($N$4="General",1/2*(1-COS(2*PI()*($B21-$F$5)/$F$6))*$F$9,"Error"))))) -> 0 | G21: =IF(B21="",0,IF($B21<$G$5,0,IF($B21>'MSD Calculation'!$D$5,0,IF($N$4="Closed-form",1/2*(1-COS(2*PI()*($B21-$G$5)/$G$6))*$G$8,IF($N$4="General",1/2*(1-COS(2*PI()*($B21-$G$5)/$G$6))*$G$9,"Error"))))) -> 0 | H21: =IF(B21="",0,IF($B21<$H$5,0,IF($B21>'MSD Calculation'!$D$5,0,IF($N$4="Closed-form",1/2*(1-COS(2*PI()*($B21-$H$5)/$H$6))*$H$8,IF($N$4="General",1/2*(1-COS(2*PI()*($B21-$H$5)/$H$6))*$H$9,"Error"))))) -> 0 | I21: =IF(B21="",0,IF($B21<$I$5,0,IF($B21>'MSD Calculation'!$D$5,0,IF($N$4="Closed-form",1/2*(1-COS(2*PI()*($B21-$I$5)/$I$6))*$I$8,IF($N$4="General",1/2*(1-COS(2*PI()*($B21-$I$5)/$I$6))*$I$9,"Error"))))) -> 0 | J21: m | L21: 0.04 | M21: =L21/'MSD Calculation'!$D$5 -> 0.0013513514 | N21: ='MSD Calculation'!$D$24-L21 -> 18.46 | O21: =E21 -> 0.014134396 | P21: =E21+F21 -> 0.014134396 | Q21: =E21+F21+G21 -> 0.014134396 | R21: =+E21+F21+G21+H21 -> 0.014134396 | S21: =E21+F21+G21+H21+I21 -> 0.014134396 | T21: m
B22: 0.05 | C22: =B22/'MSD Calculation'!$D$5 -> 0.0016891892 | D22: ='MSD Calculation'!$D$24-B22 -> 18.45 | E22: =IF(B22="",0,IF(B22<'MSD Calculation'!$D$5,$E$7*(1-B22/'MSD Calculation'!$D$5), 0)) -> 0.014129615 | F22: =IF(B22="",0,IF($B22<$F$5,0,IF($B22>'MSD Calculation'!$D$5,0,IF($N$4="Closed-form",1/2*(1-COS(2*PI()*($B22-$F$5)/$F$6))*$F$8,IF($N$4="General",1/2*(1-COS(2*PI()*($B22-$F$5)/$F$6))*$F$9,"Error"))))) -> 0 | G22: =IF(B22="",0,IF($B22<$G$5,0,IF($B22>'MSD Calculation'!$D$5,0,IF($N$4="Closed-form",1/2*(1-COS(2*PI()*($B22-$G$5)/$G$6))*$G$8,IF($N$4="General",1/2*(1-COS(2*PI()*($B22-$G$5)/$G$6))*$G$9,"Error"))))) -> 0 | H22: =IF(B22="",0,IF($B22<$H$5,0,IF($B22>'MSD Calculation'!$D$5,0,IF($N$4="Closed-form",1/2*(1-COS(2*PI()*($B22-$H$5)/$H$6))*$H$8,IF($N$4="General",1/2*(1-COS(2*PI()*($B22-$H$5)/$H$6))*$H$9,"Error"))))) -> 0 | I22: =IF(B22="",0,IF($B22<$I$5,0,IF($B22>'MSD Calculation'!$D$5,0,IF($N$4="Closed-form",1/2*(1-COS(2*PI()*($B22-$I$5)/$I$6))*$I$8,IF($N$4="General",1/2*(1-COS(2*PI()*($B22-$I$5)/$I$6))*$I$9,"Error"))))) -> 0 | J22: m | L22: 0.05 | M22: =L22/'MSD Calculation'!$D$5 -> 0.0016891892 | N22: ='MSD Calculation'!$D$24-L22 -> 18.45 | O22: =E22 -> 0.014129615 | P22: =E22+F22 -> 0.014129615 | Q22: =E22+F22+G22 -> 0.014129615 | R22: =+E22+F22+G22+H22 -> 0.014129615 | S22: =E22+F22+G22+H22+I22 -> 0.014129615 | T22: m
B23: 0.06 | C23: =B23/'MSD Calculation'!$D$5 -> 0.002027027 | D23: ='MSD Calculation'!$D$24-B23 -> 18.44 | E23: =IF(B23="",0,IF(B23<'MSD Calculation'!$D$5,$E$7*(1-B23/'MSD Calculation'!$D$5), 0)) -> 0.014124833 | F23: =IF(B23="",0,IF($B23<$F$5,0,IF($B23>'MSD Calculation'!$D$5,0,IF($N$4="Closed-form",1/2*(1-COS(2*PI()*($B23-$F$5)/$F$6))*$F$8,IF($N$4="General",1/2*(1-COS(2*PI()*($B23-$F$5)/$F$6))*$F$9,"Error"))))) -> 0 | G23: =IF(B23="",0,IF($B23<$G$5,0,IF($B23>'MSD Calculation'!$D$5,0,IF($N$4="Closed-form",1/2*(1-COS(2*PI()*($B23-$G$5)/$G$6))*$G$8,IF($N$4="General",1/2*(1-COS(2*PI()*($B23-$G$5)/$G$6))*$G$9,"Error"))))) -> 0 | H23: =IF(B23="",0,IF($B23<$H$5,0,IF($B23>'MSD Calculation'!$D$5,0,IF($N$4="Closed-form",1/2*(1-COS(2*PI()*($B23-$H$5)/$H$6))*$H$8,IF($N$4="General",1/2*(1-COS(2*PI()*($B23-$H$5)/$H$6))*$H$9,"Error"))))) -> 0 | I23: =IF(B23="",0,IF($B23<$I$5,0,IF($B23>'MSD Calculation'!$D$5,0,IF($N$4="Closed-form",1/2*(1-COS(2*PI()*($B23-$I$5)/$I$6))*$I$8,IF($N$4="General",1/2*(1-COS(2*PI()*($B23-$I$5)/$I$6))*$I$9,"Error"))))) -> 0 | J23: m | L23: 0.06 | M23: =L23/'MSD Calculation'!$D$5 -> 0.002027027 | N23: ='MSD Calculation'!$D$24-L23 -> 18.44 | O23: =E23 -> 0.014124833 | P23: =E23+F23 -> 0.014124833 | Q23: =E23+F23+G23 -> 0.014124833 | R23: =+E23+F23+G23+H23 -> 0.014124833 | S23: =E23+F23+G23+H23+I23 -> 0.014124833 | T23: m
B24: 0.07 | C24: =B24/'MSD Calculation'!$D$5 -> 0.0023648649 | D24: ='MSD Calculation'!$D$24-B24 -> 18.43 | E24: =IF(B24="",0,IF(B24<'MSD Calculation'!$D$5,$E$7*(1-B24/'MSD Calculation'!$D$5), 0)) -> 0.014120051 | F24: =IF(B24="",0,IF($B24<$F$5,0,IF($B24>'MSD Calculation'!$D$5,0,IF($N$4="Closed-form",1/2*(1-COS(2*PI()*($B24-$F$5)/$F$6))*$F$8,IF($N$4="General",1/2*(1-COS(2*PI()*($B24-$F$5)/$F$6))*$F$9,"Error"))))) -> 0 | G24: =IF(B24="",0,IF($B24<$G$5,0,IF($B24>'MSD Calculation'!$D$5,0,IF($N$4="Closed-form",1/2*(1-COS(2*PI()*($B24-$G$5)/$G$6))*$G$8,IF($N$4="General",1/2*(1-COS(2*PI()*($B24-$G$5)/$G$6))*$G$9,"Error"))))) -> 0 | H24: =IF(B24="",0,IF($B24<$H$5,0,IF($B24>'MSD Calculation'!$D$5,0,IF($N$4="Closed-form",1/2*(1-COS(2*PI()*($B24-$H$5)/$H$6))*$H$8,IF($N$4="General",1/2*(1-COS(2*PI()*($B24-$H$5)/$H$6))*$H$9,"Error"))))) -> 0 | I24: =IF(B24="",0,IF($B24<$I$5,0,IF($B24>'MSD Calculation'!$D$5,0,IF($N$4="Closed-form",1/2*(1-COS(2*PI()*($B24-$I$5)/$I$6))*$I$8,IF($N$4="General",1/2*(1-COS(2*PI()*($B24-$I$5)/$I$6))*$I$9,"Error"))))) -> 0 | J24: m | L24: 0.07 | M24: =L24/'MSD Calculation'!$D$5 -> 0.0023648649 | N24: ='MSD Calculation'!$D$24-L24 -> 18.43 | O24: =E24 -> 0.014120051 | P24: =E24+F24 -> 0.014120051 | Q24: =E24+F24+G24 -> 0.014120051 | R24: =+E24+F24+G24+H24 -> 0.014120051 | S24: =E24+F24+G24+H24+I24 -> 0.014120051 | T24: m
B25: 0.08 | C25: =B25/'MSD Calculation'!$D$5 -> 0.0027027027 | D25: ='MSD Calculation'!$D$24-B25 -> 18.42 | E25: =IF(B25="",0,IF(B25<'MSD Calculation'!$D$5,$E$7*(1-B25/'MSD Calculation'!$D$5), 0)) -> 0.01411527 | F25: =IF(B25="",0,IF($B25<$F$5,0,IF($B25>'MSD Calculation'!$D$5,0,IF($N$4="Closed-form",1/2*(1-COS(2*PI()*($B25-$F$5)/$F$6))*$F$8,IF($N$4="General",1/2*(1-COS(2*PI()*($B25-$F$5)/$F$6))*$F$9,"Error"))))) -> 0 | G25: =IF(B25="",0,IF($B25<$G$5,0,IF($B25>'MSD Calculation'!$D$5,0,IF($N$4="Closed-form",1/2*(1-COS(2*PI()*($B25-$G$5)/$G$6))*$G$8,IF($N$4="General",1/2*(1-COS(2*PI()*($B25-$G$5)/$G$6))*$G$9,"Error"))))) -> 0 | H25: =IF(B25="",0,IF($B25<$H$5,0,IF($B25>'MSD Calculation'!$D$5,0,IF($N$4="Closed-form",1/2*(1-COS(2*PI()*($B25-$H$5)/$H$6))*$H$8,IF($N$4="General",1/2*(1-COS(2*PI()*($B25-$H$5)/$H$6))*$H$9,"Error"))))) -> 0 | I25: =IF(B25="",0,IF($B25<$I$5,0,IF($B25>'MSD Calculation'!$D$5,0,IF($N$4="Closed-form",1/2*(1-COS(2*PI()*($B25-$I$5)/$I$6))*$I$8,IF($N$4="General",1/2*(1-COS(2*PI()*($B25-$I$5)/$I$6))*$I$9,"Error"))))) -> 0 | J25: m | L25: 0.08 | M25: =L25/'MSD Calculation'!$D$5 -> 0.0027027027 | N25: ='MSD Calculation'!$D$24-L25 -> 18.42 | O25: =E25 -> 0.01411527 | P25: =E25+F25 -> 0.01411527 | Q25: =E25+F25+G25 -> 0.01411527 | R25: =+E25+F25+G25+H25 -> 0.01411527 | S25: =E25+F25+G25+H25+I25 -> 0.01411527 | T25: m
B26: 0.09 | C26: =B26/'MSD Calculation'!$D$5 -> 0.0030405405 | D26: ='MSD Calculation'!$D$24-B26 -> 18.41 | E26: =IF(B26="",0,IF(B26<'MSD Calculation'!$D$5,$E$7*(1-B26/'MSD Calculation'!$D$5), 0)) -> 0.014110488 | F26: =IF(B26="",0,IF($B26<$F$5,0,IF($B26>'MSD Calculation'!$D$5,0,IF($N$4="Closed-form",1/2*(1-COS(2*PI()*($B26-$F$5)/$F$6))*$F$8,IF($N$4="General",1/2*(1-COS(2*PI()*($B26-$F$5)/$F$6))*$F$9,"Error"))))) -> 0 | G26: =IF(B26="",0,IF($B26<$G$5,0,IF($B26>'MSD Calculation'!$D$5,0,IF($N$4="Closed-form",1/2*(1-COS(2*PI()*($B26-$G$5)/$G$6))*$G$8,IF($N$4="General",1/2*(1-COS(2*PI()*($B26-$G$5)/$G$6))*$G$9,"Error"))))) -> 0 | H26: =IF(B26="",0,IF($B26<$H$5,0,IF($B26>'MSD Calculation'!$D$5,0,IF($N$4="Closed-form",1/2*(1-COS(2*PI()*($B26-$H$5)/$H$6))*$H$8,IF($N$4="General",1/2*(1-COS(2*PI()*($B26-$H$5)/$H$6))*$H$9,"Error"))))) -> 0 | I26: =IF(B26="",0,IF($B26<$I$5,0,IF($B26>'MSD Calculation'!$D$5,0,IF($N$4="Closed-form",1/2*(1-COS(2*PI()*($B26-$I$5)/$I$6))*$I$8,IF($N$4="General",1/2*(1-COS(2*PI()*($B26-$I$5)/$I$6))*$I$9,"Error"))))) -> 0 | J26: m | L26: 0.09 | M26: =L26/'MSD Calculation'!$D$5 -> 0.0030405405 | N26: ='MSD Calculation'!$D$24-L26 -> 18.41 | O26: =E26 -> 0.014110488 | P26: =E26+F26 -> 0.014110488 | Q26: =E26+F26+G26 -> 0.014110488 | R26: =+E26+F26+G26+H26 -> 0.014110488 | S26: =E26+F26+G26+H26+I26 -> 0.014110488 | T26: m
B27: 0.1 | C27: =B27/'MSD Calculation'!$D$5 -> 0.0033783784 | D27: ='MSD Calculation'!$D$24-B27 -> 18.4 | E27: =IF(B27="",0,IF(B27<'MSD Calculation'!$D$5,$E$7*(1-B27/'MSD Calculation'!$D$5), 0)) -> 0.014105707 | F27: =IF(B27="",0,IF($B27<$F$5,0,IF($B27>'MSD Calculation'!$D$5,0,IF($N$4="Closed-form",1/2*(1-COS(2*PI()*($B27-$F$5)/$F$6))*$F$8,IF($N$4="General",1/2*(1-COS(2*PI()*($B27-$F$5)/$F$6))*$F$9,"Error"))))) -> 0 | G27: =IF(B27="",0,IF($B27<$G$5,0,IF($B27>'MSD Calculation'!$D$5,0,IF($N$4="Closed-form",1/2*(1-COS(2*PI()*($B27-$G$5)/$G$6))*$G$8,IF($N$4="General",1/2*(1-COS(2*PI()*($B27-$G$5)/$G$6))*$G$9,"Error"))))) -> 0 | H27: =IF(B27="",0,IF($B27<$H$5,0,IF($B27>'MSD Calculation'!$D$5,0,IF($N$4="Closed-form",1/2*(1-COS(2*PI()*($B27-$H$5)/$H$6))*$H$8,IF($N$4="General",1/2*(1-COS(2*PI()*($B27-$H$5)/$H$6))*$H$9,"Error"))))) -> 0 | I27: =IF(B27="",0,IF($B27<$I$5,0,IF($B27>'MSD Calculation'!$D$5,0,IF($N$4="Closed-form",1/2*(1-COS(2*PI()*($B27-$I$5)/$I$6))*$I$8,IF($N$4="General",1/2*(1-COS(2*PI()*($B27-$I$5)/$I$6))*$I$9,"Error"))))) -> 0 | J27: m | L27: 0.1 | M27: =L27/'MSD Calculation'!$D$5 -> 0.0033783784 | N27: ='MSD Calculation'!$D$24-L27 -> 18.4 | O27: =E27 -> 0.014105707 | P27: =E27+F27 -> 0.014105707 | Q27: =E27+F27+G27 -> 0.014105707 | R27: =+E27+F27+G27+H27 -> 0.014105707 | S27: =E27+F27+G27+H27+I27 -> 0.014105707 | T27: m
B28: 0.11 | C28: =B28/'MSD Calculation'!$D$5 -> 0.0037162162 | D28: ='MSD Calculation'!$D$24-B28 -> 18.39 | E28: =IF(B28="",0,IF(B28<'MSD Calculation'!$D$5,$E$7*(1-B28/'MSD Calculation'!$D$5), 0)) -> 0.014100925 | F28: =IF(B28="",0,IF($B28<$F$5,0,IF($B28>'MSD Calculation'!$D$5,0,IF($N$4="Closed-form",1/2*(1-COS(2*PI()*($B28-$F$5)/$F$6))*$F$8,IF($N$4="General",1/2*(1-COS(2*PI()*($B28-$F$5)/$F$6))*$F$9,"Error"))))) -> 0 | G28: =IF(B28="",0,IF($B28<$G$5,0,IF($B28>'MSD Calculation'!$D$5,0,IF($N$4="Closed-form",1/2*(1-COS(2*PI()*($B28-$G$5)/$G$6))*$G$8,IF($N$4="General",1/2*(1-COS(2*PI()*($B28-$G$5)/$G$6))*$G$9,"Error"))))) -> 0 | H28: =IF(B28="",0,IF($B28<$H$5,0,IF($B28>'MSD Calculation'!$D$5,0,IF($N$4="Closed-form",1/2*(1-COS(2*PI()*($B28-$H$5)/$H$6))*$H$8,IF($N$4="General",1/2*(1-COS(2*PI()*($B28-$H$5)/$H$6))*$H$9,"Error"))))) -> 0 | I28: =IF(B28="",0,IF($B28<$I$5,0,IF($B28>'MSD Calculation'!$D$5,0,IF($N$4="Closed-form",1/2*(1-COS(2*PI()*($B28-$I$5)/$I$6))*$I$8,IF($N$4="General",1/2*(1-COS(2*PI()*($B28-$I$5)/$I$6))*$I$9,"Error"))))) -> 0 | J28: m | L28: 0.11 | M28: =L28/'MSD Calculation'!$D$5 -> 0.0037162162 | N28: ='MSD Calculation'!$D$24-L28 -> 18.39 | O28: =E28 -> 0.014100925 | P28: =E28+F28 -> 0.014100925 | Q28: =E28+F28+G28 -> 0.014100925 | R28: =+E28+F28+G28+H28 -> 0.014100925 | S28: =E28+F28+G28+H28+I28 -> 0.014100925 | T28: m
B29: 0.12 | C29: =B29/'MSD Calculation'!$D$5 -> 0.0040540541 | D29: ='MSD Calculation'!$D$24-B29 -> 18.38 | E29: =IF(B29="",0,IF(B29<'MSD Calculation'!$D$5,$E$7*(1-B29/'MSD Calculation'!$D$5), 0)) -> 0.014096143 | F29: =IF(B29="",0,IF($B29<$F$5,0,IF($B29>'MSD Calculation'!$D$5,0,IF($N$4="Closed-form",1/2*(1-COS(2*PI()*($B29-$F$5)/$F$6))*$F$8,IF($N$4="General",1/2*(1-COS(2*PI()*($B29-$F$5)/$F$6))*$F$9,"Error"))))) -> 0 | G29: =IF(B29="",0,IF($B29<$G$5,0,IF($B29>'MSD Calculation'!$D$5,0,IF($N$4="Closed-form",1/2*(1-COS(2*PI()*($B29-$G$5)/$G$6))*$G$8,IF($N$4="General",1/2*(1-COS(2*PI()*($B29-$G$5)/$G$6))*$G$9,"Error"))))) -> 0 | H29: =IF(B29="",0,IF($B29<$H$5,0,IF($B29>'MSD Calculation'!$D$5,0,IF($N$4="Closed-form",1/2*(1-COS(2*PI()*($B29-$H$5)/$H$6))*$H$8,IF($N$4="General",1/2*(1-COS(2*PI()*($B29-$H$5)/$H$6))*$H$9,"Error"))))) -> 0 | I29: =IF(B29="",0,IF($B29<$I$5,0,IF($B29>'MSD Calculation'!$D$5,0,IF($N$4="Closed-form",1/2*(1-COS(2*PI()*($B29-$I$5)/$I$6))*$I$8,IF($N$4="General",1/2*(1-COS(2*PI()*($B29-$I$5)/$I$6))*$I$9,"Error"))))) -> 0 | J29: m | L29: 0.12 | M29: =L29/'MSD Calculation'!$D$5 -> 0.0040540541 | N29: ='MSD Calculation'!$D$24-L29 -> 18.38 | O29: =E29 -> 0.014096143 | P29: =E29+F29 -> 0.014096143 | Q29: =E29+F29+G29 -> 0.014096143 | R29: =+E29+F29+G29+H29 -> 0.014096143 | S29: =E29+F29+G29+H29+I29 -> 0.014096143 | T29: m
... B2977: 29.6 | C2977: =B2977/'MSD Calculation'!$D$5 -> 1 | D2977: ='MSD Calculation'!$D$24-B2977 -> -11.1 | E2977: =IF(B2977="",0,IF(B2977<'MSD Calculation'!$D$5,$E$7*(1-B2977/'MSD Calculation'!$D$5), 0)) -> 0 | F2977: =IF(B2977="",0,IF($B2977<$F$5,0,IF($B2977>'MSD Calculation'!$D$5,0,IF($N$4="Closed-form",1/2*(1-COS(2*PI()*($B2977-$F$5)/$F$6))*$F$8,IF($N$4="General",1/2*(1-COS(2*PI()*($B2977-$F$5)/$F$6))*$F$9,"Error"))))) -> 0 | G2977: =IF(B2977="",0,IF($B2977<$G$5,0,IF($B2977>'MSD Calculation'!$D$5,0,IF($N$4="Closed-form",1/2*(1-COS(2*PI()*($B2977-$G$5)/$G$6))*$G$8,IF($N$4="General",1/2*(1-COS(2*PI()*($B2977-$G$5)/$G$6))*$G$9,"Error"))))) -> 0 | H2977: =IF(B2977="",0,IF($B2977<$H$5,0,IF($B2977>'MSD Calculation'!$D$5,0,IF($N$4="Closed-form",1/2*(1-COS(2*PI()*($B2977-$H$5)/$H$6))*$H$8,IF($N$4="General",1/2*(1-COS(2*PI()*($B2977-$H$5)/$H$6))*$H$9,"Error"))))) -> 0 | I2977: =IF(B2977="",0,IF($B2977<$I$5,0,IF($B2977>'MSD Calculation'!$D$5,0,IF($N$4="Closed-form",1/2*(1-COS(2*PI()*($B2977-$I$5)/$I$6))*$I$8,IF($N$4="General",1/2*(1-COS(2*PI()*($B2977-$I$5)/$I$6))*$I$9,"Error"))))) -> 0 | J2977: m | L2977: 29.6 | M2977: =L2977/'MSD Calculation'!$D$5 -> 1 | N2977: ='MSD Calculation'!$D$24-L2977 -> -11.1 | O2977: =E2977 -> 0 | P2977: =E2977+F2977 -> 0 | Q2977: =E2977+F2977+G2977 -> 0 | R2977: =+E2977+F2977+G2977+H2977 -> 0 | S2977: =E2977+F2977+G2977+H2977+I2977 -> 0 | T2977: m
